<?xml version="1.0"?>
<robot name="simple_robot">

  <!-- Материалы для RViz и Gazebo -->
  <material name="blue">
    <color rgba="0.0 0.0 0.8 1.0"/>
  </material>
  <material name="black">
    <color rgba="0.0 0.0 0.0 1.0"/>
  </material>
  <material name="gray">
    <color rgba="0.5 0.5 0.5 1.0"/>
  </material>

  <!-- Корпус (поднят над землёй) -->
  <link name="base_link">
    <visual>
      <geometry><box size="0.4 0.3 0.1"/></geometry>
      <origin xyz="0 0 0.05" rpy="0 0 0"/>
      <material name="blue"/>
    </visual>
    <collision>
      <geometry><box size="0.4 0.3 0.1"/></geometry>
      <origin xyz="0 0 0.05" rpy="0 0 0"/>
    </collision>
    <inertial>
      <mass value="2.0"/>
      <origin xyz="0 0 0.05" rpy="0 0 0"/>
      <inertia ixx="0.01667" ixy="0.0" ixz="0.0" 
               iyy="0.02833" iyz="0.0" 
               izz="0.04167"/>
    </inertial>
  </link>

  <gazebo reference="base_link">
    <material>Gazebo/Blue</material>
  </gazebo>

  <!-- Левое колесо -->
  <link name="left_wheel">
    <visual>
      <geometry><cylinder radius="0.05" length="0.03"/></geometry>
      <origin xyz="0 0 0" rpy="1.5708 0 0"/>
      <material name="black"/>
    </visual>
    <collision>
      <geometry><cylinder radius="0.05" length="0.03"/></geometry>
      <origin xyz="0 0 0" rpy="1.5708 0 0"/>
    </collision>
    <inertial>
      <mass value="0.5"/>
      <inertia ixx="0.000329" ixy="0.0" ixz="0.0" 
               iyy="0.000625" iyz="0.0" 
               izz="0.000329"/>
    </inertial>
  </link>

  <gazebo reference="left_wheel">
    <material>Gazebo/Black</material>
    <mu1>1.0</mu1>
    <mu2>1.0</mu2>
  </gazebo>

  <!-- Правое колесо -->
  <link name="right_wheel">
    <visual>
      <geometry><cylinder radius="0.05" length="0.03"/></geometry>
      <origin xyz="0 0 0" rpy="1.5708 0 0"/>
      <material name="black"/>
    </visual>
    <collision>
      <geometry><cylinder radius="0.05" length="0.03"/></geometry>
      <origin xyz="0 0 0" rpy="1.5708 0 0"/>
    </collision>
    <inertial>
      <mass value="0.5"/>
      <inertia ixx="0.000329" ixy="0.0" ixz="0.0" 
               iyy="0.000625" iyz="0.0" 
               izz="0.000329"/>
    </inertial>
  </link>

  <gazebo reference="right_wheel">
    <material>Gazebo/Black</material>
    <mu1>1.0</mu1>
    <mu2>1.0</mu2>
  </gazebo>

  <!-- Опорное колесико (кастер) -->
  <link name="caster_wheel">
    <visual>
      <geometry><sphere radius="0.02"/></geometry>
      <material name="gray"/>
    </visual>
    <collision>
      <geometry><sphere radius="0.02"/></geometry>
    </collision>
    <inertial>
      <mass value="0.1"/>
      <inertia ixx="0.0001" ixy="0.0" ixz="0.0" 
               iyy="0.0001" iyz="0.0" 
               izz="0.0001"/>
    </inertial>
  </link>

  <gazebo reference="caster_wheel">
    <material>Gazebo/Gray</material>
    <mu1>0.05</mu1>
    <mu2>0.05</mu2>
  </gazebo>

  <!-- Соединения -->
  <joint name="base_to_left_wheel" type="continuous">
    <parent link="base_link"/>
    <child link="left_wheel"/>
    <origin xyz="0 0.175 -0.05" rpy="0 0 0"/>
    <axis xyz="0 1 0"/>
  </joint>

  <joint name="base_to_right_wheel" type="continuous">
    <parent link="base_link"/>
    <child link="right_wheel"/>
    <origin xyz="0 -0.175 -0.05" rpy="0 0 0"/>
    <axis xyz="0 1 0"/>
  </joint>

  <joint name="base_to_caster" type="fixed">
    <parent link="base_link"/>
    <child link="caster_wheel"/>
    <origin xyz="-0.15 0 -0.05" rpy="0 0 0"/>
  </joint>

  <!-- Плагин дифференциального привода -->
  <gazebo>
    <plugin name="diff_drive" filename="libgazebo_ros_diff_drive.so">
      <ros>
        <namespace>/</namespace>
      </ros>
      <update_rate>50</update_rate>
      <left_joint>base_to_left_wheel</left_joint>
      <right_joint>base_to_right_wheel</right_joint>
      <wheel_separation>0.35</wheel_separation>
      <wheel_diameter>0.1</wheel_diameter>
      <max_wheel_acceleration>1.0</max_wheel_acceleration>
      <max_wheel_torque>5.0</max_wheel_torque>
      <publish_odom>true</publish_odom>
      <publish_odom_tf>true</publish_odom_tf>
      <publish_wheel_tf>true</publish_wheel_tf>
      <command_topic>cmd_vel</command_topic>
      <odometry_topic>odom</odometry_topic>
      <odometry_frame>odom</odometry_frame>
      <robot_base_frame>base_link</robot_base_frame>
    </plugin>
  </gazebo>

</robot>